Workbook

Sheet Datos
A1: MÉTODO DEL RELÉ — DATOS DEL EXPERIMENTO
A3: Amplitud del relé, d (fija): | B3: 5
A5: ε (histéresis) | B5: Pu (s) | C5: Au — pico a valle (osciloscopio) | D5: a = Au / 2 (amplitud de pico) | E5: Ku = 4d / (π·√(a²−ε²))
A6: 0.1 | B6: 0.2962 | C6: 0.2759 | D6: =C6/2 -> 0.13795 | E6: =4*$B$3/(PI()*SQRT(D6^2-A6^2)) -> 66.993301
A7: 0.2 | B7: 0.4396 | C7: 0.4829 | D7: =C7/2 -> 0.24145 | E7: =4*$B$3/(PI()*SQRT(D7^2-A7^2)) -> 47.062728
A8: 0.3 | B8: 0.5766 | C8: 0.6844 | D8: =C8/2 -> 0.3422 | E8: =4*$B$3/(PI()*SQRT(D8^2-A8^2)) -> 38.671298
A9: 0.5 | B9: 0.8401 | C9: 1.0839 | D9: =C9/2 -> 0.54195 | E9: =4*$B$3/(PI()*SQRT(D9^2-A9^2)) -> 30.450239
A10: 0.7 | B10: 1.0988 | C10: 1.482 | D10: =C10/2 -> 0.741 | E10: =4*$B$3/(PI()*SQRT(D10^2-A10^2)) -> 26.191249
A11: 1 | B11: 1.5066 | C11: 2.0848 | D11: =C11/2 -> 1.0424 | E11: =4*$B$3/(PI()*SQRT(D11^2-A11^2)) -> 21.6335

Sheet PI
A1: SINTONIZACIÓN P / PI — Ziegler & Nichols (ciclo último, vía relé)
D3: Ziegler-Nichols - P | G3: Ziegler-Nichols - PI
D4: Kp = 0.5·Ku | E4: MS (%) | F4: Ts | G4: Kp = 0.45·Ku | H4: Ti = Pu/1.2 | I4: Ki = Kp/Ti | J4: MS (%) | K4: Ts
A5: =Datos!A6 -> 0.1 | B5: =Datos!E6 -> 66.993301 | C5: =Datos!B6 -> 0.2962 | D5: =0.5*B5 -> 33.496651 | E5: 14.55 | F5: 0.6 | G5: =0.45*B5 -> 30.146986 | H5: =C5/1.2 -> 0.24683333 | I5: =G5/H5 -> 122.13499 | J5: 37.13 | K5: 1.2
A6: =Datos!A7 -> 0.2 | B6: =Datos!E7 -> 47.062728 | C6: =Datos!B7 -> 0.4396 | D6: =0.5*B6 -> 23.531364 | E6: 8.05 | F6: 0.6 | G6: =0.45*B6 -> 21.178227 | H6: =C6/1.2 -> 0.36633333 | I6: =G6/H6 -> 57.811358 | J6: 26.89 | K6: 1.8
A7: =Datos!A8 -> 0.3 | B7: =Datos!E8 -> 38.671298 | C7: =Datos!B8 -> 0.5766 | D7: =0.5*B7 -> 19.335649 | E7: 4.98 | F7: 0.7 | G7: =0.45*B7 -> 17.402084 | H7: =C7/1.2 -> 0.4805 | I7: =G7/H7 -> 36.216616 | J7: 21.45 | K7: 2.4
A8: =Datos!A9 -> 0.5 | B8: =Datos!E9 -> 30.450239 | C8: =Datos!B9 -> 0.8401 | D8: =0.5*B8 -> 15.225119 | E8: 2.01 | F8: 0.6 | G8: =0.45*B8 -> 13.702607 | H8: =C8/1.2 -> 0.70008333 | I8: =G8/H8 -> 19.572823 | J8: 15.71 | K8: 2.8
A9: =Datos!A10 -> 0.7 | B9: =Datos!E10 -> 26.191249 | C9: =Datos!B10 -> 1.0988 | D9: =0.5*B9 -> 13.095624 | E9: 0.77 | F9: 0.6 | G9: =0.45*B9 -> 11.786062 | H9: =C9/1.2 -> 0.91566667 | I9: =G9/H9 -> 12.871564 | J9: 12.96 | K9: 4.5
A10: =Datos!A11 -> 1 | B10: =Datos!E11 -> 21.6335 | C10: =Datos!B11 -> 1.5066 | D10: =0.5*B10 -> 10.81675 | E10: 0.04 | F10: 0.6 | G10: =0.45*B10 -> 9.7350751 | H10: =C10/1.2 -> 1.2555 | I10: =G10/H10 -> 7.7539428 | J10: 10.65 | K10: 7

Sheet PID
A1: SINTONIZACIÓN PID — Comparación de 4 métodos (vía relé)
D3: Ziegler & Nichols - PID | K3: Smith - PID | R3: Tan - PID | Y3: Corripio - PID
D4: Kp | E4: Ti (s) | F4: Td (s) | G4: Ki | H4: Kd | I4: MS (%) | J4: Ts | K4: Kp | L4: Ti (s) | M4: Td (s) | N4: Ki | O4: Kd | P4: MS | Q4: Ts | R4: Kp | S4: Ti (s) | T4: Td (s) | U4: Ki | V4: Kd | W4: MS | X4: Ts | Y4: Kp | Z4: Ti (s) | AA4: Td (s) | AB4: Ki | AC4: Kd | AD4: MS | AE4: Ts
A5: =Datos!A6 -> 0.1 | B5: =Datos!E6 -> 66.993301 | C5: =Datos!B6 -> 0.2962 | D5: =0.6*$B5 -> 40.195981 | E5: =0.5*$C5 -> 0.1481 | F5: =0.125*$C5 -> 0.037025 | G5: =D5/E5 -> 271.41108 | H5: =D5*F5 -> 1.4882562 | I5: 18.32 | J5: 0.8 | K5: =0.75*$B5 -> 50.244976 | L5: =0.625*$C5 -> 0.185125 | M5: =0.1*$C5 -> 0.02962 | N5: =K5/L5 -> 271.41108 | O5: =K5*M5 -> 1.4882562 | P5: 16.2 | Q5: 0.65 | R5: =0.5*$B5 -> 33.496651 | S5: =$C5 -> 0.2962 | T5: =0.125*$C5 -> 0.037025 | U5: =R5/S5 -> 113.08795 | V5: =R5*T5 -> 1.2402135 | W5: 11.97 | X5: 1.2 | Y5: =0.75*$B5 -> 50.244976 | Z5: =0.63*$C5 -> 0.186606 | AA5: =0.1*$C5 -> 0.02962 | AB5: =Y5/Z5 -> 269.25702 | AC5: =Y5*AA5 -> 1.4882562 | AD5: 16.1 | AE5: 0.8
A6: =Datos!A7 -> 0.2 | B6: =Datos!E7 -> 47.062728 | C6: =Datos!B7 -> 0.4396 | D6: =0.6*$B6 -> 28.237637 | E6: =0.5*$C6 -> 0.2198 | F6: =0.125*$C6 -> 0.05495 | G6: =D6/E6 -> 128.46968 | H6: =D6*F6 -> 1.5516581 | I6: 14.04 | J6: 1.3 | K6: =0.75*$B6 -> 35.297046 | L6: =0.625*$C6 -> 0.27475 | M6: =0.1*$C6 -> 0.04396 | N6: =K6/L6 -> 128.46968 | O6: =K6*M6 -> 1.5516581 | P6: 11.02 | Q6: 1.1 | R6: =0.5*$B6 -> 23.531364 | S6: =$C6 -> 0.4396 | T6: =0.125*$C6 -> 0.05495 | U6: =R6/S6 -> 53.529035 | V6: =R6*T6 -> 1.2930484 | W6: 9.81 | X6: 1.8 | Y6: =0.75*$B6 -> 35.297046 | Z6: =0.63*$C6 -> 0.276948 | AA6: =0.1*$C6 -> 0.04396 | AB6: =Y6/Z6 -> 127.45008 | AC6: =Y6*AA6 -> 1.5516581 | AD6: 10.95 | AE6: 1
A7: =Datos!A8 -> 0.3 | B7: =Datos!E8 -> 38.671298 | C7: =Datos!B8 -> 0.5766 | D7: =0.6*$B7 -> 23.202779 | E7: =0.5*$C7 -> 0.2883 | F7: =0.125*$C7 -> 0.072075 | G7: =D7/E7 -> 80.481369 | H7: =D7*F7 -> 1.6723403 | I7: 12.17 | J7: 1.8 | K7: =0.75*$B7 -> 29.003473 | L7: =0.625*$C7 -> 0.360375 | M7: =0.1*$C7 -> 0.05766 | N7: =K7/L7 -> 80.481369 | O7: =K7*M7 -> 1.6723403 | P7: 9.36 | Q7: 1.6 | R7: =0.5*$B7 -> 19.335649 | S7: =$C7 -> 0.5766 | T7: =0.125*$C7 -> 0.072075 | U7: =R7/S7 -> 33.533904 | V7: =R7*T7 -> 1.3936169 | W7: 8.67 | X7: 2.4 | Y7: =0.75*$B7 -> 29.003473 | Z7: =0.63*$C7 -> 0.363258 | AA7: =0.1*$C7 -> 0.05766 | AB7: =Y7/Z7 -> 79.842628 | AC7: =Y7*AA7 -> 1.6723403 | AD7: 9.3 | AE7: 1.5
A8: =Datos!A9 -> 0.5 | B8: =Datos!E9 -> 30.450239 | C8: =Datos!B9 -> 0.8401 | D8: =0.6*$B8 -> 18.270143 | E8: =0.5*$C8 -> 0.42005 | F8: =0.125*$C8 -> 0.1050125 | G8: =D8/E8 -> 43.495163 | H8: =D8*F8 -> 1.9185934 | I8: 10.14 | J8: 1.6 | K8: =0.75*$B8 -> 22.837679 | L8: =0.625*$C8 -> 0.5250625 | M8: =0.1*$C8 -> 0.08401 | N8: =K8/L8 -> 43.495163 | O8: =K8*M8 -> 1.9185934 | P8: 7.73 | Q8: 2 | R8: =0.5*$B8 -> 15.225119 | S8: =$C8 -> 0.8401 | T8: =0.125*$C8 -> 0.1050125 | U8: =R8/S8 -> 18.122985 | V8: =R8*T8 -> 1.5988278 | W8: 7.22 | X8: 2.8 | Y8: =0.75*$B8 -> 22.837679 | Z8: =0.63*$C8 -> 0.529263 | AA8: =0.1*$C8 -> 0.08401 | AB8: =Y8/Z8 -> 43.149963 | AC8: =Y8*AA8 -> 1.9185934 | AD8: 7.68 | AE8: 1.9
A9: =Datos!A10 -> 0.7 | B9: =Datos!E10 -> 26.191249 | C9: =Datos!B10 -> 1.0988 | D9: =0.6*$B9 -> 15.714749 | E9: =0.5*$C9 -> 0.5494 | F9: =0.125*$C9 -> 0.13735 | G9: =D9/E9 -> 28.603475 | H9: =D9*F9 -> 2.1584208 | I9: 8.94 | J9: 3 | K9: =0.75*$B9 -> 19.643437 | L9: =0.625*$C9 -> 0.68675 | M9: =0.1*$C9 -> 0.10988 | N9: =K9/L9 -> 28.603475 | O9: =K9*M9 -> 2.1584208 | P9: 6.77 | Q9: 3 | R9: =0.5*$B9 -> 13.095624 | S9: =$C9 -> 1.0988 | T9: =0.125*$C9 -> 0.13735 | U9: =R9/S9 -> 11.918115 | V9: =R9*T9 -> 1.798684 | W9: 6.58 | X9: 4.5 | Y9: =0.75*$B9 -> 19.643437 | Z9: =0.63*$C9 -> 0.692244 | AA9: =0.1*$C9 -> 0.10988 | AB9: =Y9/Z9 -> 28.376463 | AC9: =Y9*AA9 -> 2.1584208 | AD9: 6.73 | AE9: 3
A10: =Datos!A11 -> 1 | B10: =Datos!E11 -> 21.6335 | C10: =Datos!B11 -> 1.5066 | D10: =0.6*$B10 -> 12.9801 | E10: =0.5*$C10 -> 0.7533 | F10: =0.125*$C10 -> 0.188325 | G10: =D10/E10 -> 17.230984 | H10: =D10*F10 -> 2.4444774 | I10: 7.87 | J10: 5 | K10: =0.75*$B10 -> 16.225125 | L10: =0.625*$C10 -> 0.941625 | M10: =0.1*$C10 -> 0.15066 | N10: =K10/L10 -> 17.230984 | O10: =K10*M10 -> 2.4444774 | P10: 5.94 | Q10: 4 | R10: =0.5*$B10 -> 10.81675 | S10: =$C10 -> 1.5066 | T10: =0.125*$C10 -> 0.188325 | U10: =R10/S10 -> 7.1795766 | V10: =R10*T10 -> 2.0370645 | W10: 5.83 | X10: 7 | Y10: =0.75*$B10 -> 16.225125 | Z10: =0.63*$C10 -> 0.949158 | AA10: =0.1*$C10 -> 0.15066 | AB10: =Y10/Z10 -> 17.09423 | AC10: =Y10*AA10 -> 2.4444774 | AD10: 5.91 | AE10: 4

Sheet Análisis
A1: ANÁLISIS DE DESEMPEÑO — SELECCIÓN DE LA MEJOR SINTONÍA
A2: Criterio: menor sobreimpulso (MS) y menor tiempo de asentamiento (Ts) — datos tal como los mediste tú. Agrupado por ε: se comparan los 6 métodos entre sí para cada ε.
A4: 1. TABLA COMPLETA — 36 combinaciones (6 valores de ε × 6 métodos)
A5: Método | B5: ε | C5: Kp | D5: Ti (s) | E5: Td (s) | F5: Ki | G5: Kd | H5: MS (%) | I5: Ts (s) | J5: Rank MS | K5: Rank Ts | L5: Score | M5: Rank en el ε | N5: Desempate
A6: Ziegler-Nichols - P | B6: =PI!A5 -> 0.1 | C6: =PI!D5 -> 33.496651 | D6: — | E6: — | F6: — | G6: — | H6: =VALUE(PI!E5) -> 14.55 | I6: =VALUE(PI!F5) -> 0.6 | J6: =RANK(H6,$H$6:$H$11,1) -> 2 | K6: =RANK(I6,$I$6:$I$11,1) -> 1 | L6: =J6+K6 -> 3 | M6: =RANK(N6,$N$6:$N$11,1) -> 1 | N6: =L6+H6/1000+I6/100000 -> 3.014556
A7: Ziegler-Nichols - PI | B7: =PI!A5 -> 0.1 | C7: =PI!G5 -> 30.146986 | D7: =PI!H5 -> 0.24683333 | E7: — | F7: =PI!I5 -> 122.13499 | G7: — | H7: =VALUE(PI!J5) -> 37.13 | I7: =VALUE(PI!K5) -> 1.2 | J7: =RANK(H7,$H$6:$H$11,1) -> 6 | K7: =RANK(I7,$I$6:$I$11,1) -> 5 | L7: =J7+K7 -> 11 | M7: =RANK(N7,$N$6:$N$11,1) -> 6 | N7: =L7+H7/1000+I7/100000 -> 11.037142
A8: Ziegler-Nichols - PID | B8: =PI!A5 -> 0.1 | C8: =PID!D5 -> 40.195981 | D8: =PID!E5 -> 0.1481 | E8: =PID!F5 -> 0.037025 | F8: =PID!G5 -> 271.41108 | G8: =PID!H5 -> 1.4882562 | H8: =VALUE(PID!I5) -> 18.32 | I8: =VALUE(PID!J5) -> 0.8 | J8: =RANK(H8,$H$6:$H$11,1) -> 5 | K8: =RANK(I8,$I$6:$I$11,1) -> 3 | L8: =J8+K8 -> 8 | M8: =RANK(N8,$N$6:$N$11,1) -> 5 | N8: =L8+H8/1000+I8/100000 -> 8.018328
A9: Smith - PID | B9: =PI!A5 -> 0.1 | C9: =PID!K5 -> 50.244976 | D9: =PID!L5 -> 0.185125 | E9: =PID!M5 -> 0.02962 | F9: =PID!N5 -> 271.41108 | G9: =PID!O5 -> 1.4882562 | H9: =VALUE(PID!P5) -> 16.2 | I9: =VALUE(PID!Q5) -> 0.65 | J9: =RANK(H9,$H$6:$H$11,1) -> 4 | K9: =RANK(I9,$I$6:$I$11,1) -> 2 | L9: =J9+K9 -> 6 | M9: =RANK(N9,$N$6:$N$11,1) -> 4 | N9: =L9+H9/1000+I9/100000 -> 6.0162065
A10: Tan - PID | B10: =PI!A5 -> 0.1 | C10: =PID!R5 -> 33.496651 | D10: =PID!S5 -> 0.2962 | E10: =PID!T5 -> 0.037025 | F10: =PID!U5 -> 113.08795 | G10: =PID!V5 -> 1.2402135 | H10: =VALUE(PID!W5) -> 11.97 | I10: =VALUE(PID!X5) -> 1.2 | J10: =RANK(H10,$H$6:$H$11,1) -> 1 | K10: =RANK(I10,$I$6:$I$11,1) -> 5 | L10: =J10+K10 -> 6 | M10: =RANK(N10,$N$6:$N$11,1) -> 2 | N10: =L10+H10/1000+I10/100000 -> 6.011982
A11: Corripio - PID | B11: =PI!A5 -> 0.1 | C11: =PID!Y5 -> 50.244976 | D11: =PID!Z5 -> 0.186606 | E11: =PID!AA5 -> 0.02962 | F11: =PID!AB5 -> 269.25702 | G11: =PID!AC5 -> 1.4882562 | H11: =VALUE(PID!AD5) -> 16.1 | I11: =VALUE(PID!AE5) -> 0.8 | J11: =RANK(H11,$H$6:$H$11,1) -> 3 | K11: =RANK(I11,$I$6:$I$11,1) -> 3 | L11: =J11+K11 -> 6 | M11: =RANK(N11,$N$6:$N$11,1) -> 3 | N11: =L11+H11/1000+I11/100000 -> 6.016108
A12: Ziegler-Nichols - P | B12: =PI!A6 -> 0.2 | C12: =PI!D6 -> 23.531364 | D12: — | E12: — | F12: — | G12: — | H12: =VALUE(PI!E6) -> 8.05 | I12: =VALUE(PI!F6) -> 0.6 | J12: =RANK(H12,$H$12:$H$17,1) -> 1 | K12: =RANK(I12,$I$12:$I$17,1) -> 1 | L12: =J12+K12 -> 2 | M12: =RANK(N12,$N$12:$N$17,1) -> 1 | N12: =L12+H12/1000+I12/100000 -> 2.008056
A13: Ziegler-Nichols - PI | B13: =PI!A6 -> 0.2 | C13: =PI!G6 -> 21.178227 | D13: =PI!H6 -> 0.36633333 | E13: — | F13: =PI!I6 -> 57.811358 | G13: — | H13: =VALUE(PI!J6) -> 26.89 | I13: =VALUE(PI!K6) -> 1.8 | J13: =RANK(H13,$H$12:$H$17,1) -> 6 | K13: =RANK(I13,$I$12:$I$17,1) -> 5 | L13: =J13+K13 -> 11 | M13: =RANK(N13,$N$12:$N$17,1) -> 6 | N13: =L13+H13/1000+I13/100000 -> 11.026908
A14: Ziegler-Nichols - PID | B14: =PI!A6 -> 0.2 | C14: =PID!D6 -> 28.237637 | D14: =PID!E6 -> 0.2198 | E14: =PID!F6 -> 0.05495 | F14: =PID!G6 -> 128.46968 | G14: =PID!H6 -> 1.5516581 | H14: =VALUE(PID!I6) -> 14.04 | I14: =VALUE(PID!J6) -> 1.3 | J14: =RANK(H14,$H$12:$H$17,1) -> 5 | K14: =RANK(I14,$I$12:$I$17,1) -> 4 | L14: =J14+K14 -> 9 | M14: =RANK(N14,$N$12:$N$17,1) -> 5 | N14: =L14+H14/1000+I14/100000 -> 9.014053
A15: Smith - PID | B15: =PI!A6 -> 0.2 | C15: =PID!K6 -> 35.297046 | D15: =PID!L6 -> 0.27475 | E15: =PID!M6 -> 0.04396 | F15: =PID!N6 -> 128.46968 | G15: =PID!O6 -> 1.5516581 | H15: =VALUE(PID!P6) -> 11.02 | I15: =VALUE(PID!Q6) -> 1.1 | J15: =RANK(H15,$H$12:$H$17,1) -> 4 | K15: =RANK(I15,$I$12:$I$17,1) -> 3 | L15: =J15+K15 -> 7 | M15: =RANK(N15,$N$12:$N$17,1) -> 4 | N15: =L15+H15/1000+I15/100000 -> 7.011031
A16: Tan - PID | B16: =PI!A6 -> 0.2 | C16: =PID!R6 -> 23.531364 | D16: =PID!S6 -> 0.4396 | E16: =PID!T6 -> 0.05495 | F16: =PID!U6 -> 53.529035 | G16: =PID!V6 -> 1.2930484 | H16: =VALUE(PID!W6) -> 9.81 | I16: =VALUE(PID!X6) -> 1.8 | J16: =RANK(H16,$H$12:$H$17,1) -> 2 | K16: =RANK(I16,$I$12:$I$17,1) -> 5 | L16: =J16+K16 -> 7 | M16: =RANK(N16,$N$12:$N$17,1) -> 3 | N16: =L16+H16/1000+I16/100000 -> 7.009828
A17: Corripio - PID | B17: =PI!A6 -> 0.2 | C17: =PID!Y6 -> 35.297046 | D17: =PID!Z6 -> 0.276948 | E17: =PID!AA6 -> 0.04396 | F17: =PID!AB6 -> 127.45008 | G17: =PID!AC6 -> 1.5516581 | H17: =VALUE(PID!AD6) -> 10.95 | I17: =VALUE(PID!AE6) -> 1 | J17: =RANK(H17,$H$12:$H$17,1) -> 3 | K17: =RANK(I17,$I$12:$I$17,1) -> 2 | L17: =J17+K17 -> 5 | M17: =RANK(N17,$N$12:$N$17,1) -> 2 | N17: =L17+H17/1000+I17/100000 -> 5.01096
A18: Ziegler-Nichols - P | B18: =PI!A7 -> 0.3 | C18: =PI!D7 -> 19.335649 | D18: — | E18: — | F18: — | G18: — | H18: =VALUE(PI!E7) -> 4.98 | I18: =VALUE(PI!F7) -> 0.7 | J18: =RANK(H18,$H$18:$H$23,1) -> 1 | K18: =RANK(I18,$I$18:$I$23,1) -> 1 | L18: =J18+K18 -> 2 | M18: =RANK(N18,$N$18:$N$23,1) -> 1 | N18: =L18+H18/1000+I18/100000 -> 2.004987
A19: Ziegler-Nichols - PI | B19: =PI!A7 -> 0.3 | C19: =PI!G7 -> 17.402084 | D19: =PI!H7 -> 0.4805 | E19: — | F19: =PI!I7 -> 36.216616 | G19: — | H19: =VALUE(PI!J7) -> 21.45 | I19: =VALUE(PI!K7) -> 2.4 | J19: =RANK(H19,$H$18:$H$23,1) -> 6 | K19: =RANK(I19,$I$18:$I$23,1) -> 5 | L19: =J19+K19 -> 11 | M19: =RANK(N19,$N$18:$N$23,1) -> 6 | N19: =L19+H19/1000+I19/100000 -> 11.021474
A20: Ziegler-Nichols - PID | B20: =PI!A7 -> 0.3 | C20: =PID!D7 -> 23.202779 | D20: =PID!E7 -> 0.2883 | E20: =PID!F7 -> 0.072075 | F20: =PID!G7 -> 80.481369 | G20: =PID!H7 -> 1.6723403 | H20: =VALUE(PID!I7) -> 12.17 | I20: =VALUE(PID!J7) -> 1.8 | J20: =RANK(H20,$H$18:$H$23,1) -> 5 | K20: =RANK(I20,$I$18:$I$23,1) -> 4 | L20: =J20+K20 -> 9 | M20: =RANK(N20,$N$18:$N$23,1) -> 5 | N20: =L20+H20/1000+I20/100000 -> 9.012188
A21: Smith - PID | B21: =PI!A7 -> 0.3 | C21: =PID!K7 -> 29.003473 | D21: =PID!L7 -> 0.360375 | E21: =PID!M7 -> 0.05766 | F21: =PID!N7 -> 80.481369 | G21: =PID!O7 -> 1.6723403 | H21: =VALUE(PID!P7) -> 9.36 | I21: =VALUE(PID!Q7) -> 1.6 | J21: =RANK(H21,$H$18:$H$23,1) -> 4 | K21: =RANK(I21,$I$18:$I$23,1) -> 3 | L21: =J21+K21 -> 7 | M21: =RANK(N21,$N$18:$N$23,1) -> 4 | N21: =L21+H21/1000+I21/100000 -> 7.009376
A22: Tan - PID | B22: =PI!A7 -> 0.3 | C22: =PID!R7 -> 19.335649 | D22: =PID!S7 -> 0.5766 | E22: =PID!T7 -> 0.072075 | F22: =PID!U7 -> 33.533904 | G22: =PID!V7 -> 1.3936169 | H22: =VALUE(PID!W7) -> 8.67 | I22: =VALUE(PID!X7) -> 2.4 | J22: =RANK(H22,$H$18:$H$23,1) -> 2 | K22: =RANK(I22,$I$18:$I$23,1) -> 5 | L22: =J22+K22 -> 7 | M22: =RANK(N22,$N$18:$N$23,1) -> 3 | N22: =L22+H22/1000+I22/100000 -> 7.008694
A23: Corripio - PID | B23: =PI!A7 -> 0.3 | C23: =PID!Y7 -> 29.003473 | D23: =PID!Z7 -> 0.363258 | E23: =PID!AA7 -> 0.05766 | F23: =PID!AB7 -> 79.842628 | G23: =PID!AC7 -> 1.6723403 | H23: =VALUE(PID!AD7) -> 9.3 | I23: =VALUE(PID!AE7) -> 1.5 | J23: =RANK(H23,$H$18:$H$23,1) -> 3 | K23: =RANK(I23,$I$18:$I$23,1) -> 2 | L23: =J23+K23 -> 5 | M23: =RANK(N23,$N$18:$N$23,1) -> 2 | N23: =L23+H23/1000+I23/100000 -> 5.009315
A24: Ziegler-Nichols - P | B24: =PI!A8 -> 0.5 | C24: =PI!D8 -> 15.225119 | D24: — | E24: — | F24: — | G24: — | H24: =VALUE(PI!E8) -> 2.01 | I24: =VALUE(PI!F8) -> 0.6 | J24: =RANK(H24,$H$24:$H$29,1) -> 1 | K24: =RANK(I24,$I$24:$I$29,1) -> 1 | L24: =J24+K24 -> 2 | M24: =RANK(N24,$N$24:$N$29,1) -> 1 | N24: =L24+H24/1000+I24/100000 -> 2.002016
A25: Ziegler-Nichols - PI | B25: =PI!A8 -> 0.5 | C25: =PI!G8 -> 13.702607 | D25: =PI!H8 -> 0.70008333 | E25: — | F25: =PI!I8 -> 19.572823 | G25: — | H25: =VALUE(PI!J8) -> 15.71 | I25: =VALUE(PI!K8) -> 2.8 | J25: =RANK(H25,$H$24:$H$29,1) -> 6 | K25: =RANK(I25,$I$24:$I$29,1) -> 5 | L25: =J25+K25 -> 11 | M25: =RANK(N25,$N$24:$N$29,1) -> 6 | N25: =L25+H25/1000+I25/100000 -> 11.015738
A26: Ziegler-Nichols - PID | B26: =PI!A8 -> 0.5 | C26: =PID!D8 -> 18.270143 | D26: =PID!E8 -> 0.42005 | E26: =PID!F8 -> 0.1050125 | F26: =PID!G8 -> 43.495163 | G26: =PID!H8 -> 1.9185934 | H26: =VALUE(PID!I8) -> 10.14 | I26: =VALUE(PID!J8) -> 1.6 | J26: =RANK(H26,$H$24:$H$29,1) -> 5 | K26: =RANK(I26,$I$24:$I$29,1) -> 2 | L26: =J26+K26 -> 7 | M26: =RANK(N26,$N$24:$N$29,1) -> 4 | N26: =L26+H26/1000+I26/100000 -> 7.010156
A27: Smith - PID | B27: =PI!A8 -> 0.5 | C27: =PID!K8 -> 22.837679 | D27: =PID!L8 -> 0.5250625 | E27: =PID!M8 -> 0.08401 | F27: =PID!N8 -> 43.495163 | G27: =PID!O8 -> 1.9185934 | H27: =VALUE(PID!P8) -> 7.73 | I27: =VALUE(PID!Q8) -> 2 | J27: =RANK(H27,$H$24:$H$29,1) -> 4 | K27: =RANK(I27,$I$24:$I$29,1) -> 4 | L27: =J27+K27 -> 8 | M27: =RANK(N27,$N$24:$N$29,1) -> 5 | N27: =L27+H27/1000+I27/100000 -> 8.00775
A28: Tan - PID | B28: =PI!A8 -> 0.5 | C28: =PID!R8 -> 15.225119 | D28: =PID!S8 -> 0.8401 | E28: =PID!T8 -> 0.1050125 | F28: =PID!U8 -> 18.122985 | G28: =PID!V8 -> 1.5988278 | H28: =VALUE(PID!W8) -> 7.22 | I28: =VALUE(PID!X8) -> 2.8 | J28: =RANK(H28,$H$24:$H$29,1) -> 2 | K28: =RANK(I28,$I$24:$I$29,1) -> 5 | L28: =J28+K28 -> 7 | M28: =RANK(N28,$N$24:$N$29,1) -> 3 | N28: =L28+H28/1000+I28/100000 -> 7.007248
A29: Corripio - PID | B29: =PI!A8 -> 0.5 | C29: =PID!Y8 -> 22.837679 | D29: =PID!Z8 -> 0.529263 | E29: =PID!AA8 -> 0.08401 | F29: =PID!AB8 -> 43.149963 | G29: =PID!AC8 -> 1.9185934 | H29: =VALUE(PID!AD8) -> 7.68 | I29: =VALUE(PID!AE8) -> 1.9 | J29: =RANK(H29,$H$24:$H$29,1) -> 3 | K29: =RANK(I29,$I$24:$I$29,1) -> 3 | L29: =J29+K29 -> 6 | M29: =RANK(N29,$N$24:$N$29,1) -> 2 | N29: =L29+H29/1000+I29/100000 -> 6.007699
A30: Ziegler-Nichols - P | B30: =PI!A9 -> 0.7 | C30: =PI!D9 -> 13.095624 | D30: — | E30: — | F30: — | G30: — | H30: =VALUE(PI!E9) -> 0.77 | I30: =VALUE(PI!F9) -> 0.6 | J30: =RANK(H30,$H$30:$H$35,1) -> 1 | K30: =RANK(I30,$I$30:$I$35,1) -> 1 | L30: =J30+K30 -> 2 | M30: =RANK(N30,$N$30:$N$35,1) -> 1 | N30: =L30+H30/1000+I30/100000 -> 2.000776
A31: Ziegler-Nichols - PI | B31: =PI!A9 -> 0.7 | C31: =PI!G9 -> 11.786062 | D31: =PI!H9 -> 0.91566667 | E31: — | F31: =PI!I9 -> 12.871564 | G31: — | H31: =VALUE(PI!J9) -> 12.96 | I31: =VALUE(PI!K9) -> 4.5 | J31: =RANK(H31,$H$30:$H$35,1) -> 6 | K31: =RANK(I31,$I$30:$I$35,1) -> 5 | L31: =J31+K31 -> 11 | M31: =RANK(N31,$N$30:$N$35,1) -> 6 | N31: =L31+H31/1000+I31/100000 -> 11.013005
A32: Ziegler-Nichols - PID | B32: =PI!A9 -> 0.7 | C32: =PID!D9 -> 15.714749 | D32: =PID!E9 -> 0.5494 | E32: =PID!F9 -> 0.13735 | F32: =PID!G9 -> 28.603475 | G32: =PID!H9 -> 2.1584208 | H32: =VALUE(PID!I9) -> 8.94 | I32: =VALUE(PID!J9) -> 3 | J32: =RANK(H32,$H$30:$H$35,1) -> 5 | K32: =RANK(I32,$I$30:$I$35,1) -> 2 | L32: =J32+K32 -> 7 | M32: =RANK(N32,$N$30:$N$35,1) -> 5 | N32: =L32+H32/1000+I32/100000 -> 7.00897
A33: Smith - PID | B33: =PI!A9 -> 0.7 | C33: =PID!K9 -> 19.643437 | D33: =PID!L9 -> 0.68675 | E33: =PID!M9 -> 0.10988 | F33: =PID!N9 -> 28.603475 | G33: =PID!O9 -> 2.1584208 | H33: =VALUE(PID!P9) -> 6.77 | I33: =VALUE(PID!Q9) -> 3 | J33: =RANK(H33,$H$30:$H$35,1) -> 4 | K33: =RANK(I33,$I$30:$I$35,1) -> 2 | L33: =J33+K33 -> 6 | M33: =RANK(N33,$N$30:$N$35,1) -> 3 | N33: =L33+H33/1000+I33/100000 -> 6.0068
A34: Tan - PID | B34: =PI!A9 -> 0.7 | C34: =PID!R9 -> 13.095624 | D34: =PID!S9 -> 1.0988 | E34: =PID!T9 -> 0.13735 | F34: =PID!U9 -> 11.918115 | G34: =PID!V9 -> 1.798684 | H34: =VALUE(PID!W9) -> 6.58 | I34: =VALUE(PID!X9) -> 4.5 | J34: =RANK(H34,$H$30:$H$35,1) -> 2 | K34: =RANK(I34,$I$30:$I$35,1) -> 5 | L34: =J34+K34 -> 7 | M34: =RANK(N34,$N$30:$N$35,1) -> 4 | N34: =L34+H34/1000+I34/100000 -> 7.006625
A35: Corripio - PID | B35: =PI!A9 -> 0.7 | C35: =PID!Y9 -> 19.643437 | D35: =PID!Z9 -> 0.692244 | E35: =PID!AA9 -> 0.10988 | F35: =PID!AB9 -> 28.376463 | G35: =PID!AC9 -> 2.1584208 | H35: =VALUE(PID!AD9) -> 6.73 | I35: =VALUE(PID!AE9) -> 3 | J35: =RANK(H35,$H$30:$H$35,1) -> 3 | K35: =RANK(I35,$I$30:$I$35,1) -> 2 | L35: =J35+K35 -> 5 | M35: =RANK(N35,$N$30:$N$35,1) -> 2 | N35: =L35+H35/1000+I35/100000 -> 5.00676
A36: Ziegler-Nichols - P | B36: =PI!A10 -> 1 | C36: =PI!D10 -> 10.81675 | D36: — | E36: — | F36: — | G36: — | H36: =VALUE(PI!E10) -> 0.04 | I36: =VALUE(PI!F10) -> 0.6 | J36: =RANK(H36,$H$36:$H$41,1) -> 1 | K36: =RANK(I36,$I$36:$I$41,1) -> 1 | L36: =J36+K36 -> 2 | M36: =RANK(N36,$N$36:$N$41,1) -> 1 | N36: =L36+H36/1000+I36/100000 -> 2.000046
A37: Ziegler-Nichols - PI | B37: =PI!A10 -> 1 | C37: =PI!G10 -> 9.7350751 | D37: =PI!H10 -> 1.2555 | E37: — | F37: =PI!I10 -> 7.7539428 | G37: — | H37: =VALUE(PI!J10) -> 10.65 | I37: =VALUE(PI!K10) -> 7 | J37: =RANK(H37,$H$36:$H$41,1) -> 6 | K37: =RANK(I37,$I$36:$I$41,1) -> 5 | L37: =J37+K37 -> 11 | M37: =RANK(N37,$N$36:$N$41,1) -> 6 | N37: =L37+H37/1000+I37/100000 -> 11.01072
A38: Ziegler-Nichols - PID | B38: =PI!A10 -> 1 | C38: =PID!D10 -> 12.9801 | D38: =PID!E10 -> 0.7533 | E38: =PID!F10 -> 0.188325 | F38: =PID!G10 -> 17.230984 | G38: =PID!H10 -> 2.4444774 | H38: =VALUE(PID!I10) -> 7.87 | I38: =VALUE(PID!J10) -> 5 | J38: =RANK(H38,$H$36:$H$41,1) -> 5 | K38: =RANK(I38,$I$36:$I$41,1) -> 4 | L38: =J38+K38 -> 9 | M38: =RANK(N38,$N$36:$N$41,1) -> 5 | N38: =L38+H38/1000+I38/100000 -> 9.00792
A39: Smith - PID | B39: =PI!A10 -> 1 | C39: =PID!K10 -> 16.225125 | D39: =PID!L10 -> 0.941625 | E39: =PID!M10 -> 0.15066 | F39: =PID!N10 -> 17.230984 | G39: =PID!O10 -> 2.4444774 | H39: =VALUE(PID!P10) -> 5.94 | I39: =VALUE(PID!Q10) -> 4 | J39: =RANK(H39,$H$36:$H$41,1) -> 4 | K39: =RANK(I39,$I$36:$I$41,1) -> 2 | L39: =J39+K39 -> 6 | M39: =RANK(N39,$N$36:$N$41,1) -> 3 | N39: =L39+H39/1000+I39/100000 -> 6.00598
A40: Tan - PID | B40: =PI!A10 -> 1 | C40: =PID!R10 -> 10.81675 | D40: =PID!S10 -> 1.5066 | E40: =PID!T10 -> 0.188325 | F40: =PID!U10 -> 7.1795766 | G40: =PID!V10 -> 2.0370645 | H40: =VALUE(PID!W10) -> 5.83 | I40: =VALUE(PID!X10) -> 7 | J40: =RANK(H40,$H$36:$H$41,1) -> 2 | K40: =RANK(I40,$I$36:$I$41,1) -> 5 | L40: =J40+K40 -> 7 | M40: =RANK(N40,$N$36:$N$41,1) -> 4 | N40: =L40+H40/1000+I40/100000 -> 7.0059
A41: Corripio - PID | B41: =PI!A10 -> 1 | C41: =PID!Y10 -> 16.225125 | D41: =PID!Z10 -> 0.949158 | E41: =PID!AA10 -> 0.15066 | F41: =PID!AB10 -> 17.09423 | G41: =PID!AC10 -> 2.4444774 | H41: =VALUE(PID!AD10) -> 5.91 | I41: =VALUE(PID!AE10) -> 4 | J41: =RANK(H41,$H$36:$H$41,1) -> 3 | K41: =RANK(I41,$I$36:$I$41,1) -> 2 | L41: =J41+K41 -> 5 | M41: =RANK(N41,$N$36:$N$41,1) -> 2 | N41: =L41+H41/1000+I41/100000 -> 5.00595
...
